<mujoco model="gen3">
  <compiler angle="radian" meshdir="assets" autolimits="true"/>

  <option integrator="implicitfast" cone="elliptic" impratio="10"/>

  <asset>
    <material name="metal" rgba="0.58 0.58 0.58 1"/>
    <material name="silicone" rgba="0.1882 0.1882 0.1882 1"/>
    <material name="gray" rgba="0.4627 0.4627 0.4627 1"/>
    <material name="black" rgba="0.149 0.149 0.149 1"/>
    <material name="arm_plates" rgba="0.75294 0.75294 0.75294 1"/>

    <!-- Bob Gripper -->
    <mesh name="bob_base_mount" class="2f85" file="./gripper_assets/base_mount.stl"/>
    <mesh name="bob_base" class="2f85" file="./gripper_assets/base.stl"/>
    <mesh name="bob_driver" class="2f85" file="./gripper_assets/driver.stl"/>
    <mesh name="bob_coupler" class="2f85" file="./gripper_assets/coupler.stl"/>
    <mesh name="bob_follower" class="2f85" file="./gripper_assets/follower.stl"/>
    <mesh name="bob_pad" class="2f85" file="./gripper_assets/pad.stl"/>
    <mesh name="bob_silicone_pad" class="2f85" file="./gripper_assets/silicone_pad.stl"/>
    <mesh name="bob_spring_link" class="2f85" file="./gripper_assets/spring_link.stl"/>
    <!-- Bob Kinova Gen3 Arm -->
    <mesh name="bob_base_link" file="./kinova_assets/base_link.stl"/>
    <mesh name="bob_shoulder_link" file="./kinova_assets/shoulder_link.stl"/>
    <mesh name="bob_half_arm_1_link" file="./kinova_assets/half_arm_1_link.stl"/>
    <mesh name="bob_half_arm_2_link" file="./kinova_assets/half_arm_2_link.stl"/>
    <mesh name="bob_forearm_link" file="./kinova_assets/forearm_link.stl"/>
    <mesh name="bob_spherical_wrist_1_link" file="./kinova_assets/spherical_wrist_1_link.stl"/>
    <mesh name="bob_spherical_wrist_2_link" file="./kinova_assets/spherical_wrist_2_link.stl"/>
    <mesh name="bob_bracelet_with_vision_link" file="./kinova_assets/bracelet_with_vision_link.stl"/>

    <!-- Alice Gripper -->
    <mesh name="alice_base_mount" class="2f85" file="./gripper_assets/base_mount.stl"/>
    <mesh name="alice_base" class="2f85" file="./gripper_assets/base.stl"/>
    <mesh name="alice_driver" class="2f85" file="./gripper_assets/driver.stl"/>
    <mesh name="alice_coupler" class="2f85" file="./gripper_assets/coupler.stl"/>
    <mesh name="alice_follower" class="2f85" file="./gripper_assets/follower.stl"/>
    <mesh name="alice_pad" class="2f85" file="./gripper_assets/pad.stl"/>
    <mesh name="alice_silicone_pad" class="2f85" file="./gripper_assets/silicone_pad.stl"/>
    <mesh name="alice_spring_link" class="2f85" file="./gripper_assets/spring_link.stl"/>
    <!-- Alice Kinova Gen3 Arm -->
    <mesh name="alice_base_link" file="./kinova_assets/base_link.stl"/>
    <mesh name="alice_shoulder_link" file="./kinova_assets/shoulder_link.stl"/>
    <mesh name="alice_half_arm_1_link" file="./kinova_assets/half_arm_1_link.stl"/>
    <mesh name="alice_half_arm_2_link" file="./kinova_assets/half_arm_2_link.stl"/>
    <mesh name="alice_forearm_link" file="./kinova_assets/forearm_link.stl"/>
    <mesh name="alice_spherical_wrist_1_link" file="./kinova_assets/spherical_wrist_1_link.stl"/>
    <mesh name="alice_spherical_wrist_2_link" file="./kinova_assets/spherical_wrist_2_link.stl"/>
    <mesh name="alice_bracelet_with_vision_link" file="./kinova_assets/bracelet_with_vision_link.stl"/>
  </asset>
  
  <default>
    <default class="visual">
      <geom type="mesh" contype="0" conaffinity="0" group="2"/>
    </default>
    <default class="collision">
      <geom type="mesh" group="3"/>
      <default class="pad_box1">
        <geom mass="0" type="box" pos="0 -0.0026 0.028125" size="0.011 0.004 0.009375" friction="0.7"
          solimp="0.95 0.99 0.001" solref="0.004 1" priority="1" rgba="0.55 0.55 0.55 1"/>
      </default>
      <default class="pad_box2">
        <geom mass="0" type="box" pos="0 -0.0026 0.009375" size="0.011 0.004 0.009375" friction="0.6"
          solimp="0.95 0.99 0.001" solref="0.004 1" priority="1" rgba="0.45 0.45 0.45 1"/>
      </default>
    </default>
    <default class="large_actuator">
      <position kp="2000" kv="100" forcerange="-105 105"/>
    </default>
    <default class="small_actuator">
      <position kp="500" kv="50" forcerange="-52 52"/>
    </default>
    <site size="0.001" rgba="0.5 0.5 0.5 0.3" group="4"/>

    <default class="2f85">
      <mesh scale="0.001 0.001 0.001"/>
      <general biastype="affine"/>

      <joint axis="1 0 0"/>
      <default class="driver">
        <joint range="0 0.8" armature="0.005" damping="0.1" solimplimit="0.95 0.99 0.001" solreflimit="0.005 1"/>
      </default>
      <default class="follower">
        <joint range="-0.872664 0.872664" armature="0.001" pos="0 -0.018 0.0065" solimplimit="0.95 0.99 0.001" solreflimit="0.005 1"/>
      </default>
      <default class="spring_link">
        <joint range="-0.29670597283 0.8" armature="0.001" stiffness="0.05" springref="2.62" damping="0.00125"/>
      </default>
      <default class="coupler">
        <joint range="-1.57 0" armature="0.001" solimplimit="0.95 0.99 0.001" solreflimit="0.005 1"/>
      </default>
    </default>
  </default>
  
  
  <worldbody>
    <body name="bob_base_link" pos="-0.5 0.0 0.0">
      <inertial pos="-0.000648 -0.000166 0.084487" quat="0.999294 0.00139618 -0.0118387 0.035636" mass="1.697" diaginertia="0.00462407 0.00449437 0.00207755"/>
      <geom class="visual" mesh="bob_base_link" rgba="0.99215686 0.70980392 0.08235294 1"/>
      <geom class="collision" mesh="bob_base_link"/>
      <body name="bob_shoulder_link" pos="0 0 0.15643" quat="0 1 0 0">
        <inertial pos="-2.3e-05 -0.010364 -0.07336" quat="0.707051 0.0451246 -0.0453544 0.704263" mass="1.3773" diaginertia="0.00488868 0.00457 0.00135132"/>
        <joint name="bob_joint_1"/>
        <geom class="visual" mesh="bob_shoulder_link" material="arm_plates"/>
        <geom class="collision" mesh="bob_shoulder_link"/>
        <body name="bob_half_arm_1_link" pos="0 0.005375 -0.12838" quat="1 1 0 0">
          <inertial pos="-4.4e-05 -0.09958 -0.013278" quat="0.482348 0.516286 -0.516862 0.483366" mass="1.1636" diaginertia="0.0113017 0.011088 0.00102532"/>
          <joint name="bob_joint_2" range="-2.24 2.24"/>
          <geom class="visual" mesh="bob_half_arm_1_link" material="arm_plates"/>
          <geom class="collision" mesh="bob_half_arm_1_link"/>
          <body name="bob_half_arm_2_link" pos="0 -0.21038 -0.006375" quat="1 -1 0 0">
            <inertial pos="-4.4e-05 -0.006641 -0.117892" quat="0.706144 0.0213722 -0.0209128 0.707437" mass="1.1636" diaginertia="0.0111633 0.010932 0.00100671"/>
            <joint name="bob_joint_3"/>
            <geom class="visual" mesh="bob_half_arm_2_link" material="arm_plates"/>
            <geom class="collision" mesh="bob_half_arm_2_link"/>
            <body name="bob_forearm_link" pos="0 0.006375 -0.21038" quat="1 1 0 0">
              <inertial pos="-1.8e-05 -0.075478 -0.015006" quat="0.483678 0.515961 -0.515859 0.483455" mass="0.9302" diaginertia="0.00834839 0.008147 0.000598606"/>
              <joint name="bob_joint_4" range="-2.57 2.57"/>
              <geom class="visual" mesh="bob_forearm_link" material="arm_plates"/>
              <geom class="collision" mesh="bob_forearm_link"/>
              <body name="bob_spherical_wrist_1_link" pos="0 -0.20843 -0.006375" quat="1 -1 0 0">
                <inertial pos="1e-06 -0.009432 -0.063883" quat="0.703558 0.0707492 -0.0707492 0.703558" mass="0.6781" diaginertia="0.00165901 0.001596 0.000346988"/>
                <joint name="bob_joint_5"/>
                <geom class="visual" mesh="bob_spherical_wrist_1_link" material="arm_plates"/>
                <geom class="collision" mesh="bob_spherical_wrist_1_link"/>
                <body name="bob_spherical_wrist_2_link" pos="0 0.00017505 -0.10593" quat="1 1 0 0">
                  <inertial pos="1e-06 -0.045483 -0.00965" quat="0.44426 0.550121 -0.550121 0.44426" mass="0.6781" diaginertia="0.00170087 0.001641 0.00035013"/>
                  <joint name="bob_joint_6" range="-2.09 2.09"/>
                  <geom class="visual" mesh="bob_spherical_wrist_2_link" material="arm_plates"/>
                  <geom class="collision" mesh="bob_spherical_wrist_2_link"/>
                  <body name="bob_bracelet_link" pos="0 -0.10593 -0.00017505" quat="1 -1 0 0">
                    <inertial pos="0.000281 0.011402 -0.029798" quat="0.394358 0.596779 -0.577293 0.393789" mass="0.5" diaginertia="0.000657336 0.000587019 0.000320645"/>
                    <joint name="bob_joint_7"/>
                    <geom class="visual" mesh="bob_bracelet_with_vision_link" material="arm_plates"/>
                    <geom class="collision" mesh="bob_bracelet_with_vision_link"/>
                    <camera name="bob_wrist" pos="0 -0.05639 -0.058475" quat="0 0 0 1" fovy="41.83792730009236" resolution="640 480"/>
                    <site name="bob_pinch_site" pos="0 0 -0.061525" quat="0 1 0 0"/>
                    
                    <!-- Bob's Gripper -->
                    <body name="bob_base_mount" pos="0 0 -0.054525" quat="0 1 0 0" childclass="2f85">
                      <geom class="visual" mesh="bob_base_mount" material="black"/>
                      <geom class="collision" mesh="bob_base_mount"/>
                      <body name="bob_base" pos="0 0 0.0038" quat="1 0 0 1">
                        <inertial mass="0.777441" pos="0 -2.70394e-05 0.0354675" quat="1 -0.00152849 0 0" diaginertia="0.000260285 0.000225381 0.000152708"/>
                        <geom class="visual" mesh="bob_base" material="black"/>
                        <geom class="collision" mesh="bob_base"/>
                        <site name="bob_pinch" pos="0 0 0.145" type="sphere" group="5" rgba="0.9 0.9 0.9 1" size="0.005"/>
                        <!-- Right-hand side 4-bar linkage -->
                        <body name="bob_right_driver" pos="0 0.0306011 0.054904">
                          <inertial mass="0.00899563" pos="2.96931e-12 0.0177547 0.00107314" quat="0.681301 0.732003 0 0" diaginertia="1.72352e-06 1.60906e-06 3.22006e-07"/>
                          <joint name="bob_right_driver_joint" class="driver"/>
                          <geom class="visual" mesh="bob_driver" material="gray"/>
                          <geom class="collision" mesh="bob_driver"/>
                          <body name="bob_right_coupler" pos="0 0.0315 -0.0041">
                            <inertial mass="0.0140974" pos="0 0.00301209 0.0232175" quat="0.705636 -0.0455904 0.0455904 0.705636" diaginertia="4.16206e-06 3.52216e-06 8.88131e-07"/>
                            <joint name="bob_right_coupler_joint" class="coupler"/>
                            <geom class="visual" mesh="bob_coupler" material="black"/>
                            <geom class="collision" mesh="bob_coupler"/>
                          </body>
                        </body>
                        <body name="bob_right_spring_link" pos="0 0.0132 0.0609">
                          <inertial mass="0.0221642" pos="-8.65005e-09 0.0181624 0.0212658" quat="0.663403 -0.244737 0.244737 0.663403" diaginertia="8.96853e-06 6.71733e-06 2.63931e-06"/>
                          <joint name="bob_right_spring_link_joint" class="spring_link"/>
                          <geom class="visual" mesh="bob_spring_link" material="black"/>
                          <geom class="collision" mesh="bob_spring_link"/>
                          <body name="bob_right_follower" pos="0 0.055 0.0375">
                            <inertial mass="0.0125222" pos="0 -0.011046 0.0124786" quat="1 0.1664 0 0" diaginertia="2.67415e-06 2.4559e-06 6.02031e-07"/>
                            <joint name="bob_right_follower_joint" class="follower"/>
                            <geom class="visual" mesh="bob_follower" material="black"/>
                            <geom class="collision" mesh="bob_follower"/>
                            <body name="bob_right_pad" pos="0 -0.0189 0.01352">
                              <geom class="pad_box1" name="bob_right_pad1"/>
                              <geom class="pad_box2" name="bob_right_pad2"/>
                              <inertial mass="0.0035" pos="0 -0.0025 0.0185" quat="0.707107 0 0 0.707107" diaginertia="4.73958e-07 3.64583e-07 1.23958e-07"/>
                              <geom class="visual" mesh="bob_pad"/>
                              <body name="bob_right_silicone_pad">
                                <geom class="visual" mesh="bob_silicone_pad" material="black"/>
                              </body>
                            </body>
                          </body>
                        </body>
                        <!-- Left-hand side 4-bar linkage -->
                        <body name="bob_left_driver" pos="0 -0.0306011 0.054904" quat="0 0 0 1">
                          <inertial mass="0.00899563" pos="0 0.0177547 0.00107314" quat="0.681301 0.732003 0 0" diaginertia="1.72352e-06 1.60906e-06 3.22006e-07"/>
                          <joint name="bob_left_driver_joint" class="driver"/>
                          <geom class="visual" mesh="bob_driver" material="gray"/>
                          <geom class="collision" mesh="bob_driver"/>
                          <body name="bob_left_coupler" pos="0 0.0315 -0.0041">
                            <inertial mass="0.0140974" pos="0 0.00301209 0.0232175" quat="0.705636 -0.0455904 0.0455904 0.705636" diaginertia="4.16206e-06 3.52216e-06 8.88131e-07"/>
                            <joint name="bob_left_coupler_joint" class="coupler"/>
                            <geom class="visual" mesh="bob_coupler" material="black"/>
                            <geom class="collision" mesh="bob_coupler"/>
                          </body>
                        </body>
                        <body name="bob_left_spring_link" pos="0 -0.0132 0.0609" quat="0 0 0 1">
                          <inertial mass="0.0221642" pos="-8.65005e-09 0.0181624 0.0212658" quat="0.663403 -0.244737 0.244737 0.663403" diaginertia="8.96853e-06 6.71733e-06 2.63931e-06"/>
                          <joint name="bob_left_spring_link_joint" class="spring_link"/>
                          <geom class="visual" mesh="bob_spring_link" material="black"/>
                          <geom class="collision" mesh="bob_spring_link"/>
                          <body name="bob_left_follower" pos="0 0.055 0.0375">
                            <inertial mass="0.0125222" pos="0 -0.011046 0.0124786" quat="1 0.1664 0 0" diaginertia="2.67415e-06 2.4559e-06 6.02031e-07"/>
                            <joint name="bob_left_follower_joint" class="follower"/>
                            <geom class="visual" mesh="bob_follower" material="black"/>
                            <geom class="collision" mesh="bob_follower"/>
                            <body name="bob_left_pad" pos="0 -0.0189 0.01352">
                              <geom class="pad_box1" name="bob_left_pad1"/>
                              <geom class="pad_box2" name="bob_left_pad2"/>
                              <inertial mass="0.0035" pos="0 -0.0025 0.0185" quat="1 0 0 1" diaginertia="4.73958e-07 3.64583e-07 1.23958e-07"/>
                              <geom class="visual" mesh="bob_pad"/>
                              <body name="bob_left_silicone_pad">
                                <geom class="visual" mesh="bob_silicone_pad" material="black"/>
                              </body>
                            </body>
                          </body>
                        </body>
                      </body>
                    </body>

                  </body>
                </body>
              </body>
            </body>
          </body>
        </body>
      </body>
    </body>

    <body name="alice_base_link" pos="0.5 0.0 0.0" quat="0.0 0.0 0.0 1.0">
      <inertial pos="-0.000648 -0.000166 0.084487" quat="0.999294 0.00139618 -0.0118387 0.035636" mass="1.697" diaginertia="0.00462407 0.00449437 0.00207755" />
      <geom class="visual" mesh="alice_base_link" rgba="0.0 0.14901961 0.4627451 1"/>
      <geom class="collision" mesh="alice_base_link"/>
      <body name="alice_shoulder_link" pos="0 0 0.15643" quat="0 1 0 0">
        <inertial pos="-2.3e-05 -0.010364 -0.07336" quat="0.707051 0.0451246 -0.0453544 0.704263" mass="1.3773" diaginertia="0.00488868 0.00457 0.00135132"/>
        <joint name="alice_joint_1"/>
        <geom class="visual" mesh="alice_shoulder_link" material="arm_plates"/>
        <geom class="collision" mesh="alice_shoulder_link"/>
        <body name="alice_half_arm_1_link" pos="0 0.005375 -0.12838" quat="1 1 0 0">
          <inertial pos="-4.4e-05 -0.09958 -0.013278" quat="0.482348 0.516286 -0.516862 0.483366" mass="1.1636" diaginertia="0.0113017 0.011088 0.00102532"/>
          <joint name="alice_joint_2" range="-2.24 2.24"/>
          <geom class="visual" mesh="alice_half_arm_1_link" material="arm_plates"/>
          <geom class="collision" mesh="alice_half_arm_1_link"/>
          <body name="alice_half_arm_2_link" pos="0 -0.21038 -0.006375" quat="1 -1 0 0">
            <inertial pos="-4.4e-05 -0.006641 -0.117892" quat="0.706144 0.0213722 -0.0209128 0.707437" mass="1.1636" diaginertia="0.0111633 0.010932 0.00100671"/>
            <joint name="alice_joint_3"/>
            <geom class="visual" mesh="alice_half_arm_2_link" material="arm_plates"/>
            <geom class="collision" mesh="alice_half_arm_2_link"/>
            <body name="alice_forearm_link" pos="0 0.006375 -0.21038" quat="1 1 0 0">
              <inertial pos="-1.8e-05 -0.075478 -0.015006" quat="0.483678 0.515961 -0.515859 0.483455" mass="0.9302" diaginertia="0.00834839 0.008147 0.000598606"/>
              <joint name="alice_joint_4" range="-2.57 2.57"/>
              <geom class="visual" mesh="alice_forearm_link" material="arm_plates"/>
              <geom class="collision" mesh="alice_forearm_link"/>
              <body name="alice_spherical_wrist_1_link" pos="0 -0.20843 -0.006375" quat="1 -1 0 0">
                <inertial pos="1e-06 -0.009432 -0.063883" quat="0.703558 0.0707492 -0.0707492 0.703558" mass="0.6781" diaginertia="0.00165901 0.001596 0.000346988"/>
                <joint name="alice_joint_5"/>
                <geom class="visual" mesh="alice_spherical_wrist_1_link" material="arm_plates"/>
                <geom class="collision" mesh="alice_spherical_wrist_1_link"/>
                <body name="alice_spherical_wrist_2_link" pos="0 0.00017505 -0.10593" quat="1 1 0 0">
                  <inertial pos="1e-06 -0.045483 -0.00965" quat="0.44426 0.550121 -0.550121 0.44426" mass="0.6781" diaginertia="0.00170087 0.001641 0.00035013"/>
                  <joint name="alice_joint_6" range="-2.09 2.09"/>
                  <geom class="visual" mesh="alice_spherical_wrist_2_link" material="arm_plates"/>
                  <geom class="collision" mesh="alice_spherical_wrist_2_link"/>
                  <body name="alice_bracelet_link" pos="0 -0.10593 -0.00017505" quat="1 -1 0 0">
                    <inertial pos="0.000281 0.011402 -0.029798" quat="0.394358 0.596779 -0.577293 0.393789" mass="0.5" diaginertia="0.000657336 0.000587019 0.000320645"/>
                    <joint name="alice_joint_7"/>
                    <geom class="visual" mesh="alice_bracelet_with_vision_link" material="arm_plates"/>
                    <geom class="collision" mesh="alice_bracelet_with_vision_link"/>
                    <camera name="alice_wrist" pos="0 -0.05639 -0.058475" quat="0 0 0 1" fovy="41.83792730009236" resolution="640 480"/>
                    <site name="alice_pinch_site" pos="0 0 -0.061525" quat="0 1 0 0"/>
                    
                    
                    <!-- Alice's Gripper -->
                    <body name="alice_base_mount" pos="0 0 -0.054525" quat="0 1 0 0" childclass="2f85">
                      <geom class="visual" mesh="alice_base_mount" material="black"/>
                      <geom class="collision" mesh="alice_base_mount"/>
                      <body name="alice_base" pos="0 0 0.0038" quat="1 0 0 1">
                        <inertial mass="0.777441" pos="0 -2.70394e-05 0.0354675" quat="1 -0.00152849 0 0" diaginertia="0.000260285 0.000225381 0.000152708"/>
                        <geom class="visual" mesh="alice_base" material="black"/>
                        <geom class="collision" mesh="alice_base"/>
                        <site name="alice_pinch" pos="0 0 0.145" type="sphere" group="5" rgba="0.9 0.9 0.9 1" size="0.005"/>
                        <!-- Right-hand side 4-bar linkage -->
                        <body name="alice_right_driver" pos="0 0.0306011 0.054904">
                          <inertial mass="0.00899563" pos="2.96931e-12 0.0177547 0.00107314" quat="0.681301 0.732003 0 0" diaginertia="1.72352e-06 1.60906e-06 3.22006e-07"/>
                          <joint name="alice_right_driver_joint" class="driver"/>
                          <geom class="visual" mesh="alice_driver" material="gray"/>
                          <geom class="collision" mesh="alice_driver"/>
                          <body name="alice_right_coupler" pos="0 0.0315 -0.0041">
                            <inertial mass="0.0140974" pos="0 0.00301209 0.0232175" quat="0.705636 -0.0455904 0.0455904 0.705636" diaginertia="4.16206e-06 3.52216e-06 8.88131e-07"/>
                            <joint name="alice_right_coupler_joint" class="coupler"/>
                            <geom class="visual" mesh="alice_coupler" material="black"/>
                            <geom class="collision" mesh="alice_coupler"/>
                          </body>
                        </body>
                        <body name="alice_right_spring_link" pos="0 0.0132 0.0609">
                          <inertial mass="0.0221642" pos="-8.65005e-09 0.0181624 0.0212658" quat="0.663403 -0.244737 0.244737 0.663403" diaginertia="8.96853e-06 6.71733e-06 2.63931e-06"/>
                          <joint name="alice_right_spring_link_joint" class="spring_link"/>
                          <geom class="visual" mesh="alice_spring_link" material="black"/>
                          <geom class="collision" mesh="alice_spring_link"/>
                          <body name="alice_right_follower" pos="0 0.055 0.0375">
                            <inertial mass="0.0125222" pos="0 -0.011046 0.0124786" quat="1 0.1664 0 0" diaginertia="2.67415e-06 2.4559e-06 6.02031e-07"/>
                            <joint name="alice_right_follower_joint" class="follower"/>
                            <geom class="visual" mesh="alice_follower" material="black"/>
                            <geom class="collision" mesh="alice_follower"/>
                            <body name="alice_right_pad" pos="0 -0.0189 0.01352">
                              <geom class="pad_box1" name="alice_right_pad1"/>
                              <geom class="pad_box2" name="alice_right_pad2"/>
                              <inertial mass="0.0035" pos="0 -0.0025 0.0185" quat="0.707107 0 0 0.707107" diaginertia="4.73958e-07 3.64583e-07 1.23958e-07"/>
                              <geom class="visual" mesh="alice_pad"/>
                              <body name="alice_right_silicone_pad">
                                <geom class="visual" mesh="alice_silicone_pad" material="black"/>
                              </body>
                            </body>
                          </body>
                        </body>
                        <!-- Left-hand side 4-bar linkage -->
                        <body name="alice_left_driver" pos="0 -0.0306011 0.054904" quat="0 0 0 1">
                          <inertial mass="0.00899563" pos="0 0.0177547 0.00107314" quat="0.681301 0.732003 0 0" diaginertia="1.72352e-06 1.60906e-06 3.22006e-07"/>
                          <joint name="alice_left_driver_joint" class="driver"/>
                          <geom class="visual" mesh="alice_driver" material="gray"/>
                          <geom class="collision" mesh="alice_driver"/>
                          <body name="alice_left_coupler" pos="0 0.0315 -0.0041">
                            <inertial mass="0.0140974" pos="0 0.00301209 0.0232175" quat="0.705636 -0.0455904 0.0455904 0.705636" diaginertia="4.16206e-06 3.52216e-06 8.88131e-07"/>
                            <joint name="alice_left_coupler_joint" class="coupler"/>
                            <geom class="visual" mesh="alice_coupler" material="black"/>
                            <geom class="collision" mesh="alice_coupler"/>
                          </body>
                        </body>
                        <body name="alice_left_spring_link" pos="0 -0.0132 0.0609" quat="0 0 0 1">
                          <inertial mass="0.0221642" pos="-8.65005e-09 0.0181624 0.0212658" quat="0.663403 -0.244737 0.244737 0.663403" diaginertia="8.96853e-06 6.71733e-06 2.63931e-06"/>
                          <joint name="alice_left_spring_link_joint" class="spring_link"/>
                          <geom class="visual" mesh="alice_spring_link" material="black"/>
                          <geom class="collision" mesh="alice_spring_link"/>
                          <body name="alice_left_follower" pos="0 0.055 0.0375">
                            <inertial mass="0.0125222" pos="0 -0.011046 0.0124786" quat="1 0.1664 0 0" diaginertia="2.67415e-06 2.4559e-06 6.02031e-07"/>
                            <joint name="alice_left_follower_joint" class="follower"/>
                            <geom class="visual" mesh="alice_follower" material="black"/>
                            <geom class="collision" mesh="alice_follower"/>
                            <body name="alice_left_pad" pos="0 -0.0189 0.01352">
                              <geom class="pad_box1" name="alice_left_pad1"/>
                              <geom class="pad_box2" name="alice_left_pad2"/>
                              <inertial mass="0.0035" pos="0 -0.0025 0.0185" quat="1 0 0 1" diaginertia="4.73958e-07 3.64583e-07 1.23958e-07"/>
                              <geom class="visual" mesh="alice_pad"/>
                              <body name="alice_left_silicone_pad">
                                <geom class="visual" mesh="alice_silicone_pad" material="black"/>
                              </body>
                            </body>
                          </body>
                        </body>
                      </body>
                    </body>


                  </body>
                </body>
              </body>
            </body>
          </body>
        </body>
      </body>
    </body>
  </worldbody>

  <contact>
    <exclude body1="bob_base_link" body2="bob_shoulder_link"/>
    <exclude body1="bob_base" body2="bob_left_driver"/>
    <exclude body1="bob_base" body2="bob_right_driver"/>
    <exclude body1="bob_base" body2="bob_left_spring_link"/>
    <exclude body1="bob_base" body2="bob_right_spring_link"/>
    <exclude body1="bob_right_coupler" body2="bob_right_follower"/>
    <exclude body1="bob_left_coupler" body2="bob_left_follower"/>

    <exclude body1="alice_base_link" body2="alice_shoulder_link"/>
    <exclude body1="alice_base" body2="alice_left_driver"/>
    <exclude body1="alice_base" body2="alice_right_driver"/>
    <exclude body1="alice_base" body2="alice_left_spring_link"/>
    <exclude body1="alice_base" body2="alice_right_spring_link"/>
    <exclude body1="alice_right_coupler" body2="alice_right_follower"/>
    <exclude body1="alice_left_coupler" body2="alice_left_follower"/>
  </contact>

  <tendon>
    <fixed name="bob_split">
      <joint joint="bob_right_driver_joint" coef="0.5"/>
      <joint joint="bob_left_driver_joint" coef="0.5"/>
    </fixed>

    <fixed name="alice_split">
      <joint joint="alice_right_driver_joint" coef="0.5"/>
      <joint joint="alice_left_driver_joint" coef="0.5"/>
    </fixed>
  </tendon>

  <equality>
    <connect anchor="0 0 0" body1="bob_right_follower" body2="bob_right_coupler" solimp="0.95 0.99 0.001" solref="0.005 1"/>
    <connect anchor="0 0 0" body1="bob_left_follower" body2="bob_left_coupler" solimp="0.95 0.99 0.001" solref="0.005 1"/>
    <joint joint1="bob_right_driver_joint" joint2="bob_left_driver_joint" polycoef="0 1 0 0 0" solimp="0.95 0.99 0.001" solref="0.005 1"/>

    <connect anchor="0 0 0" body1="alice_right_follower" body2="alice_right_coupler" solimp="0.95 0.99 0.001" solref="0.005 1"/>
    <connect anchor="0 0 0" body1="alice_left_follower" body2="alice_left_coupler" solimp="0.95 0.99 0.001" solref="0.005 1"/>
    <joint joint1="alice_right_driver_joint" joint2="alice_left_driver_joint" polycoef="0 1 0 0 0" solimp="0.95 0.99 0.001" solref="0.005 1"/>
  </equality>

  <actuator>
    <position class="large_actuator" name="bob_joint_1" joint="bob_joint_1"/>
    <position class="large_actuator" name="bob_joint_2" joint="bob_joint_2" ctrlrange="-2.2497294058206907 2.2497294058206907"/>
    <position class="large_actuator" name="bob_joint_3" joint="bob_joint_3"/>
    <position class="large_actuator" name="bob_joint_4" joint="bob_joint_4" ctrlrange="-2.5795966344476193 2.5795966344476193"/>
    <position class="small_actuator" name="bob_joint_5" joint="bob_joint_5"/>
    <position class="small_actuator" name="bob_joint_6" joint="bob_joint_6" ctrlrange="-2.0996310901491784 2.0996310901491784"/>
    <position class="small_actuator" name="bob_joint_7" joint="bob_joint_7"/>
    <general class="2f85" name="bob_fingers_actuator" tendon="bob_split" forcerange="-5 5" ctrlrange="0 255" gainprm="0.3137255 0 0" biasprm="0 -100 -10"/>


    <position class="large_actuator" name="alice_joint_1" joint="alice_joint_1"/>
    <position class="large_actuator" name="alice_joint_2" joint="alice_joint_2" ctrlrange="-2.2497294058206907 2.2497294058206907"/>
    <position class="large_actuator" name="alice_joint_3" joint="alice_joint_3"/>
    <position class="large_actuator" name="alice_joint_4" joint="alice_joint_4" ctrlrange="-2.5795966344476193 2.5795966344476193"/>
    <position class="small_actuator" name="alice_joint_5" joint="alice_joint_5"/>
    <position class="small_actuator" name="alice_joint_6" joint="alice_joint_6" ctrlrange="-2.0996310901491784 2.0996310901491784"/>
    <position class="small_actuator" name="alice_joint_7" joint="alice_joint_7"/>
    <general class="2f85" name="alice_fingers_actuator" tendon="alice_split" forcerange="-5 5" ctrlrange="0 255" gainprm="0.3137255 0 0" biasprm="0 -100 -10"/>
  </actuator>

  <!-- <keyframe>
    <key name="home" qpos="0 0.26179939 3.14159265 -2.26892803 0 0.95993109 1.57079633"
      ctrl="0 0.26179939 3.14159265 -2.26892803 0 0.95993109 1.57079633"/>
    <key name="retract" qpos="0 -0.34906585 3.14159265 -2.54818071 0 -0.87266463 1.57079633"
      ctrl="0 -0.34906585 3.14159265 -2.54818071 0 -0.87266463 1.57079633"/>
  </keyframe> -->
</mujoco>
